<sdf version='1.11'>
  <model name='acds_quad_base'>
    <link name='base_link'>
      <self_collide>false</self_collide>
      <pose>0.00097812079826465497 -0.00021356049216531237 0.010217855411063051 0 0 0</pose>
      <inertial>
        <pose>0 0 0 0 0 0</pose>
        <mass>0.64777735261177605</mass>
        <inertia>
          <ixx>0.0023033483674425102</ixx>
          <ixy>-5.8146395058328102e-06</ixy>
          <ixz>1.6252626996464845e-05</ixz>
          <iyy>0.0020551678163506174</iyy>
          <iyz>2.7527345086166749e-06</iyz>
          <izz>0.0042247994567047491</izz>
        </inertia>
      </inertial>
      <collision name='base_link_collision'>
        <geometry>
          <mesh>
            <uri>model://acds_quad_base/meshes/CAD/base_link.stl</uri>
            <scale>0.001 0.001 0.001</scale>
          </mesh>
        </geometry>
      </collision>
      <visual name='base_link_visual'>
        <geometry>
          <mesh>
            <uri>model://acds_quad_base/meshes/CAD/base_link.stl</uri>
            <scale>0.001 0.001 0.001</scale>
          </mesh>
        </geometry>
        <material>
          <ambient>0.0199999996 0.0199999996 0.0199999996 1</ambient>
          <diffuse>0.0500000007 0.0500000007 0.0500000007 1</diffuse>
          <specular>0.100000001 0.100000001 0.100000001 1</specular>
          <emissive>0 0 0 1</emissive>
        </material>
      </visual>
      <sensor name='air_pressure_sensor' type='air_pressure'>
        <always_on>true</always_on>
        <update_rate>50</update_rate>
        <air_pressure>
          <pressure>
            <noise type='gaussian'>
              <mean>0</mean>
              <stddev>0.01</stddev>
            </noise>
          </pressure>
        </air_pressure>
      </sensor>
      <sensor name='imu_sensor' type='imu'>
        <always_on>true</always_on>
        <update_rate>250</update_rate>
        <imu>
          <angular_velocity>
            <x>
              <noise type='gaussian'>
                <mean>0</mean>
                <stddev>0.00018665000000000001</stddev>
                <dynamic_bias_stddev>3.8785000000000002e-05</dynamic_bias_stddev>
                <dynamic_bias_correlation_time>1000</dynamic_bias_correlation_time>
              </noise>
            </x>
            <y>
              <noise type='gaussian'>
                <mean>0</mean>
                <stddev>0.00018665000000000001</stddev>
                <dynamic_bias_stddev>3.8785000000000002e-05</dynamic_bias_stddev>
                <dynamic_bias_correlation_time>1000</dynamic_bias_correlation_time>
              </noise>
            </y>
            <z>
              <noise type='gaussian'>
                <mean>0</mean>
                <stddev>0.00018665000000000001</stddev>
                <dynamic_bias_stddev>3.8785000000000002e-05</dynamic_bias_stddev>
                <dynamic_bias_correlation_time>1000</dynamic_bias_correlation_time>
              </noise>
            </z>
          </angular_velocity>
          <linear_acceleration>
            <x>
              <noise type='gaussian'>
                <mean>0</mean>
                <stddev>0.0018600000000000001</stddev>
                <dynamic_bias_stddev>0.0060000000000000001</dynamic_bias_stddev>
                <dynamic_bias_correlation_time>300</dynamic_bias_correlation_time>
              </noise>
            </x>
            <y>
              <noise type='gaussian'>
                <mean>0</mean>
                <stddev>0.0018600000000000001</stddev>
                <dynamic_bias_stddev>0.0060000000000000001</dynamic_bias_stddev>
                <dynamic_bias_correlation_time>300</dynamic_bias_correlation_time>
              </noise>
            </y>
            <z>
              <noise type='gaussian'>
                <mean>0</mean>
                <stddev>0.0018600000000000001</stddev>
                <dynamic_bias_stddev>0.0060000000000000001</dynamic_bias_stddev>
                <dynamic_bias_correlation_time>300</dynamic_bias_correlation_time>
              </noise>
            </z>
          </linear_acceleration>
        </imu>
      </sensor>
      <sensor name='navsat_sensor' type='navsat'>
        <always_on>true</always_on>
        <update_rate>30</update_rate>
      </sensor>
    </link>
    <link name='legs'>
      <self_collide>false</self_collide>
      <pose>-2.4036259595073315e-18 -4.4482893172468267e-08 -0.013522611625440432 0 0 0</pose>
      <inertial>
        <pose>0 0 0 0 0 0</pose>
        <mass>0.46189508822442449</mass>
        <inertia>
          <ixx>0.0036066059237643017</ixx>
          <ixy>-5.1464190250354317e-07</ixy>
          <ixz>-5.9005843364108265e-19</ixz>
          <iyy>0.0025868119188244888</iyy>
          <iyz>-2.092610260789753e-10</iyz>
          <izz>0.0060394739388787344</izz>
        </inertia>
      </inertial>
      <collision name='legs_collision'>
        <geometry>
          <mesh>
            <uri>model://acds_quad_base/meshes/CAD/legs.stl</uri>
            <scale>0.001 0.001 0.001</scale>
          </mesh>
        </geometry>
      </collision>
      <visual name='legs_visual'>
        <geometry>
          <mesh>
            <uri>model://acds_quad_base/meshes/CAD/legs.stl</uri>
            <scale>0.001 0.001 0.001</scale>
          </mesh>
        </geometry>
        <material>
          <ambient>0.400000006 0.170000002 0 1</ambient>
          <diffuse>1 0.409999996 0 1</diffuse>
          <specular>0.100000001 0.0500000007 0.0199999996 1</specular>
          <emissive>0 0 0 1</emissive>
        </material>
      </visual>
    </link>
    <link name='raspi_btm'>
      <self_collide>false</self_collide>
      <pose>-0.0067001265140220435 0.00046732090693628418 -0.019673215011732758 0 0 0</pose>
      <inertial>
        <pose>0 0 0 0 0 0</pose>
        <mass>0.19765503025591366</mass>
        <inertia>
          <ixx>0.00013770289438850951</ixx>
          <ixy>-1.3718756744934183e-07</ixy>
          <ixz>6.7264471228250524e-05</ixz>
          <iyy>0.00034054663102418712</iyy>
          <iyz>-9.23768823148119e-07</iyz>
          <izz>0.00038537709340174528</izz>
        </inertia>
      </inertial>
      <collision name='raspi_btm_collision'>
        <geometry>
          <mesh>
            <uri>model://acds_quad_base/meshes/CAD/raspi_btm.stl</uri>
            <scale>0.001 0.001 0.001</scale>
          </mesh>
        </geometry>
      </collision>
      <visual name='raspi_btm_visual'>
        <geometry>
          <mesh>
            <uri>model://acds_quad_base/meshes/CAD/raspi_btm.stl</uri>
            <scale>0.001 0.001 0.001</scale>
          </mesh>
        </geometry>
        <material>
          <ambient>0.400000006 0.170000002 0 1</ambient>
          <diffuse>1 0.409999996 0 1</diffuse>
          <specular>0.100000001 0.0500000007 0.0199999996 1</specular>
          <emissive>0 0 0 1</emissive>
        </material>
      </visual>
    </link>
    <link name='raspi_top'>
      <self_collide>false</self_collide>
      <pose>-0.025093617541530115 0.00033440165413599831 0.008007571119358332 0 0 0</pose>
      <inertial>
        <pose>0 0 0 0 0 0</pose>
        <mass>0.15671359795938386</mass>
        <inertia>
          <ixx>0.00014397373856783245</ixx>
          <ixy>-2.5547641730238984e-07</ixy>
          <ixz>0.00017748978331056208</ixz>
          <iyy>0.00053378448985660573</iyy>
          <iyz>-1.9933523951052338e-07</iyz>
          <izz>0.0004873652551887921</izz>
        </inertia>
      </inertial>
      <collision name='raspi_top_collision'>
        <geometry>
          <mesh>
            <uri>model://acds_quad_base/meshes/CAD/raspi_top.stl</uri>
            <scale>0.001 0.001 0.001</scale>
          </mesh>
        </geometry>
      </collision>
      <visual name='raspi_top_visual'>
        <geometry>
          <mesh>
            <uri>model://acds_quad_base/meshes/CAD/raspi_top.stl</uri>
            <scale>0.001 0.001 0.001</scale>
          </mesh>
        </geometry>
        <material>
          <ambient>0.0199999996 0.0199999996 0.0199999996 1</ambient>
          <diffuse>0.0500000007 0.0500000007 0.0500000007 1</diffuse>
          <specular>0.100000001 0.100000001 0.100000001 1</specular>
          <emissive>0 0 0 1</emissive>
        </material>
      </visual>
    </link>
    <link name='rotor_0'>
      <gravity>true</gravity>
      <self_collide>false</self_collide>
      <velocity_decay/>
      <pose>0.072682254670000002 -0.086579229049999998 0.025000000000000001 0 0 0</pose>
      <inertial>
        <mass>0.016076923076923075</mass>
        <inertia>
          <ixx>3.8464910483993325e-07</ixx>
          <iyy>2.6115851691700804e-05</iyy>
          <izz>2.6498582347140039e-05</izz>
          <ixy>0</ixy>
          <ixz>0</ixz>
          <iyz>0</iyz>
        </inertia>
      </inertial>
      <visual name='rotor_0_visual'>
        <geometry>
          <mesh>
            <uri>model://acds_quad_base/meshes/CAD/Propeller_CCW.stl</uri>
            <scale>0.001 0.001 0.001</scale>
          </mesh>
        </geometry>
        <material>
          <ambient>0.200000003 0 0.200000003 0.699999988</ambient>
          <diffuse>0.600000024 0 0.600000024 0.699999988</diffuse>
          <specular>0.100000001 0.0500000007 0.100000001 0.699999988</specular>
          <emissive>0 0 0 1</emissive>
        </material>
      </visual>
      <collision name='rotor_0_collision'>
        <geometry>
          <mesh>
            <uri>model://acds_quad_base/meshes/CAD/Propeller_CW.stl</uri>
            <scale>0.001 0.001 0.001</scale>
          </mesh>
        </geometry>
      </collision>
    </link>
    <joint name='rotor_0_joint' type='revolute'>
      <parent>base_link</parent>
      <child>rotor_0</child>
      <axis>
        <xyz>0 0 1</xyz>
        <limit>
          <lower>-10000000000000000</lower>
          <upper>10000000000000000</upper>
        </limit>
        <dynamics>
          <spring_reference>0</spring_reference>
          <spring_stiffness>0</spring_stiffness>
        </dynamics>
      </axis>
    </joint>
    <link name='rotor_1'>
      <gravity>true</gravity>
      <self_collide>false</self_collide>
      <velocity_decay/>
      <pose>-0.072682254670000002 0.086579229049999998 0.025000000000000001 0 0 0</pose>
      <inertial>
        <mass>0.016076923076923075</mass>
        <inertia>
          <ixx>3.8464910483993325e-07</ixx>
          <iyy>2.6115851691700804e-05</iyy>
          <izz>2.6498582347140039e-05</izz>
          <ixy>0</ixy>
          <ixz>0</ixz>
          <iyz>0</iyz>
        </inertia>
      </inertial>
      <visual name='rotor_1_visual'>
        <geometry>
          <mesh>
            <uri>model://acds_quad_base/meshes/CAD/Propeller_CCW.stl</uri>
            <scale>0.001 0.001 0.001</scale>
          </mesh>
        </geometry>
        <material>
          <ambient>0.200000003 0 0.200000003 0.699999988</ambient>
          <diffuse>0.600000024 0 0.600000024 0.699999988</diffuse>
          <specular>0.100000001 0.0500000007 0.100000001 0.699999988</specular>
          <emissive>0 0 0 1</emissive>
        </material>
      </visual>
      <collision name='rotor_1_collision'>
        <geometry>
          <mesh>
            <uri>model://acds_quad_base/meshes/CAD/Propeller_CW.stl</uri>
            <scale>0.001 0.001 0.001</scale>
          </mesh>
        </geometry>
      </collision>
    </link>
    <joint name='rotor_1_joint' type='revolute'>
      <parent>base_link</parent>
      <child>rotor_1</child>
      <axis>
        <xyz>0 0 1</xyz>
        <limit>
          <lower>-10000000000000000</lower>
          <upper>10000000000000000</upper>
        </limit>
        <dynamics>
          <spring_reference>0</spring_reference>
          <spring_stiffness>0</spring_stiffness>
        </dynamics>
      </axis>
    </joint>
    <link name='rotor_2'>
      <gravity>true</gravity>
      <self_collide>false</self_collide>
      <velocity_decay/>
      <pose>0.072682254670000002 0.086579229049999998 0.025000000000000001 0 0 0</pose>
      <inertial>
        <mass>0.016076923076923075</mass>
        <inertia>
          <ixx>3.8464910483993325e-07</ixx>
          <iyy>2.6115851691700804e-05</iyy>
          <izz>2.6498582347140039e-05</izz>
          <ixy>0</ixy>
          <ixz>0</ixz>
          <iyz>0</iyz>
        </inertia>
      </inertial>
      <visual name='rotor_2_visual'>
        <geometry>
          <mesh>
            <uri>model://acds_quad_base/meshes/CAD/Propeller_CCW.stl</uri>
            <scale>0.001 0.001 0.001</scale>
          </mesh>
        </geometry>
        <material>
          <ambient>0.300000012 0.300000012 0 0.600000024</ambient>
          <diffuse>1 1 0 0.600000024</diffuse>
          <specular>0.100000001 0.100000001 0.0500000007 0.600000024</specular>
          <emissive>0 0 0 1</emissive>
        </material>
      </visual>
      <collision name='rotor_2_collision'>
        <geometry>
          <mesh>
            <uri>model://acds_quad_base/meshes/CAD/Propeller_CW.stl</uri>
            <scale>0.001 0.001 0.001</scale>
          </mesh>
        </geometry>
      </collision>
    </link>
    <joint name='rotor_2_joint' type='revolute'>
      <parent>base_link</parent>
      <child>rotor_2</child>
      <axis>
        <xyz>0 0 1</xyz>
        <limit>
          <lower>-10000000000000000</lower>
          <upper>10000000000000000</upper>
        </limit>
        <dynamics>
          <spring_reference>0</spring_reference>
          <spring_stiffness>0</spring_stiffness>
        </dynamics>
      </axis>
    </joint>
    <link name='rotor_3'>
      <gravity>true</gravity>
      <self_collide>false</self_collide>
      <velocity_decay/>
      <pose>-0.072682254670000002 -0.086579229049999998 0.025000000000000001 0 0 0</pose>
      <inertial>
        <mass>0.016076923076923075</mass>
        <inertia>
          <ixx>3.8464910483993325e-07</ixx>
          <iyy>2.6115851691700804e-05</iyy>
          <izz>2.6498582347140039e-05</izz>
          <ixy>0</ixy>
          <ixz>0</ixz>
          <iyz>0</iyz>
        </inertia>
      </inertial>
      <visual name='rotor_3_visual'>
        <geometry>
          <mesh>
            <uri>model://acds_quad_base/meshes/CAD/Propeller_CCW.stl</uri>
            <scale>0.001 0.001 0.001</scale>
          </mesh>
        </geometry>
        <material>
          <ambient>0.300000012 0.300000012 0 0.600000024</ambient>
          <diffuse>1 1 0 0.600000024</diffuse>
          <specular>0.100000001 0.100000001 0.0500000007 0.600000024</specular>
          <emissive>0 0 0 1</emissive>
        </material>
      </visual>
      <collision name='rotor_3_collision'>
        <geometry>
          <mesh>
            <uri>model://acds_quad_base/meshes/CAD/Propeller_CW.stl</uri>
            <scale>0.001 0.001 0.001</scale>
          </mesh>
        </geometry>
      </collision>
    </link>
    <joint name='rotor_3_joint' type='revolute'>
      <parent>base_link</parent>
      <child>rotor_3</child>
      <axis>
        <xyz>0 0 1</xyz>
        <limit>
          <lower>-10000000000000000</lower>
          <upper>10000000000000000</upper>
        </limit>
        <dynamics>
          <spring_reference>0</spring_reference>
          <spring_stiffness>0</spring_stiffness>
        </dynamics>
      </axis>
    </joint>
    <joint name='joint_sma_base' type='fixed'>
      <parent>base_link</parent>
      <child>raspi_btm</child>
      <pose>-0.070135846106064187 -0.0099508264322743078 0.049673215011732247 0 0 0</pose>
    </joint>
    <joint name='joint_legs' type='fixed'>
      <parent>base_link</parent>
      <child>legs</child>
      <pose>0.071113528137145457 0.10450989979429313 0.016522611625440435 0 0 0</pose>
    </joint>
    <joint name='joint_antenna' type='fixed'>
      <parent>raspi_btm</parent>
      <child>raspi_top</child>
      <pose>-0.061842073704317636 0.00018209282052600542 0.018062710254879606 0 0 0</pose>
    </joint>
  </model>
</sdf>
